<?xml version="1.0" ?>
<robot name="usb" xmlns:xacro="http://www.ros.org/wiki/xacro">

<xacro:include filename="$(find usb_description)/urdf/materials.xacro" />
<xacro:include filename="$(find usb_description)/urdf/usb.trans" />
<xacro:include filename="$(find usb_description)/urdf/usb.gazebo" />
<link name="base_link">
  <inertial>
    <origin rpy="0 0 0" xyz="-6.998127749700094e-23 5.378861316410096e-05 0.023975572454417362"/>
    <mass value="1.7591494453623584"/>
    <inertia ixx="0.000873" ixy="0.0" ixz="0.0" iyy="0.003319" iyz="1e-06" izz="0.004074"/>
  </inertial>
  <visual>
    <origin rpy="0 0 0" xyz="0 0 0"/>
    <geometry>
      <mesh filename="package://usb_description/meshes/base_link.stl" scale="0.001 0.001 0.001"/>
    </geometry>
    <material name="silver"/>
  </visual>
  <collision>
    <origin rpy="0 0 0" xyz="0 0 0"/>
    <geometry>
      <mesh filename="package://usb_description/meshes/base_link.stl" scale="0.001 0.001 0.001"/>
    </geometry>
  </collision>
</link>

<link name="Castor_1">
  <inertial>
    <origin rpy="0 0 0" xyz="0.0 -7.553609602736766e-08 1.0408340855860843e-17"/>
    <mass value="0.014130675210860253"/>
    <inertia ixx="0.0" ixy="0.0" ixz="0.0" iyy="0.0" iyz="0.0" izz="0.0"/>
  </inertial>
  <visual>
    <origin rpy="0 0 0" xyz="-0.0 -0.028388 -0.009"/>
    <geometry>
      <mesh filename="package://usb_description/meshes/Castor_1.stl" scale="0.001 0.001 0.001"/>
    </geometry>
    <material name="silver"/>
  </visual>
  <collision>
    <origin rpy="0 0 0" xyz="-0.0 -0.028388 -0.009"/>
    <geometry>
      <mesh filename="package://usb_description/meshes/Castor_1.stl" scale="0.001 0.001 0.001"/>
    </geometry>
  </collision>
</link>

<link name="Wheel_1_1">
  <inertial>
    <origin rpy="0 0 0" xyz="0.0050000000000000044 2.4868995751603505e-15 -2.463307335887066e-16"/>
    <mass value="0.13465180272551203"/>
    <inertia ixx="3.8e-05" ixy="0.0" ixz="0.0" iyy="2e-05" iyz="-0.0" izz="2e-05"/>
  </inertial>
  <visual>
    <origin rpy="0 0 0" xyz="0.085 0.0 -0.024"/>
    <geometry>
      <mesh filename="package://usb_description/meshes/Wheel_1_1.stl" scale="0.001 0.001 0.001"/>
    </geometry>
    <material name="silver"/>
  </visual>
  <collision>
    <origin rpy="0 0 0" xyz="0.085 0.0 -0.024"/>
    <geometry>
      <mesh filename="package://usb_description/meshes/Wheel_1_1.stl" scale="0.001 0.001 0.001"/>
    </geometry>
  </collision>
</link>

<link name="Wheel_2_1">
  <inertial>
    <origin rpy="0 0 0" xyz="-0.0050000000000000044 -2.9753977059954196e-15 -3.122502256758253e-17"/>
    <mass value="0.13465180272551203"/>
    <inertia ixx="3.8e-05" ixy="0.0" ixz="0.0" iyy="2e-05" iyz="-0.0" izz="2e-05"/>
  </inertial>
  <visual>
    <origin rpy="0 0 0" xyz="-0.085 -0.0 -0.024"/>
    <geometry>
      <mesh filename="package://usb_description/meshes/Wheel_2_1.stl" scale="0.001 0.001 0.001"/>
    </geometry>
    <material name="silver"/>
  </visual>
  <collision>
    <origin rpy="0 0 0" xyz="-0.085 -0.0 -0.024"/>
    <geometry>
      <mesh filename="package://usb_description/meshes/Wheel_2_1.stl" scale="0.001 0.001 0.001"/>
    </geometry>
  </collision>
</link>

<joint name="Ball1" type="floating">
  <origin rpy="0 0 0" xyz="0.0 0.028388 0.009"/>
  <parent link="base_link"/>
  <child link="Castor_1"/>
</joint>

<joint name="Rev2" type="continuous">
  <origin rpy="0 0 0" xyz="-0.085 0.0 0.024"/>
  <parent link="base_link"/>
  <child link="Wheel_1_1"/>
  <axis xyz="-1.0 -0.0 -0.0"/>
</joint>

<joint name="Rev3" type="continuous">
  <origin rpy="0 0 0" xyz="0.085 0.0 0.024"/>
  <parent link="base_link"/>
  <child link="Wheel_2_1"/>
  <axis xyz="1.0 0.0 0.0"/>
</joint>

</robot>
